<robot
  name="efort_description">
  <link name="dummy_link"></link>
  <joint name="joint_0" type="fixed">
    <parent link="dummy_link"/>
    <child link="base_link"/>
    <origin rpy="0 0 0" xyz="0 0 0"/>
  </joint>
  <link
    name="base_link">
    <inertial>
      <origin
        xyz="-0.0409348834836866 5.81724498287163E-17 0.0871107778963886"
        rpy="0 0 0" />
      <mass
        value="6.87266141070566" />
      <inertia
        ixx="0.0313669036407799"
        ixy="1.04977328311514E-16"
        ixz="0.00312157290391517"
        iyy="0.0585028447746046"
        iyz="-3.34322101516448E-17"
        izz="0.0536016136829563" />
    </inertial>
    <visual>
      <origin
        xyz="0 0 0"
        rpy="0 0 0" />
      <geometry>
        <mesh
          filename="package://efort_description/meshes/base_link.STL" />
      </geometry>
      <material
        name="">
        <color
          rgba="0.792156862745098 0.819607843137255 0.933333333333333 1" />
      </material>
    </visual>
    <collision>
      <origin
        xyz="0 0 0"
        rpy="0 0 0" />
      <geometry>
        <mesh
          filename="package://efort_description/meshes/base_link.STL" />
      </geometry>
    </collision>
  </link>
  <link
    name="link_1">
    <inertial>
      <origin
        xyz="0.0235426655587023 -0.000575626480178959 0.0827164949716509"
        rpy="0 0 0" />
      <mass
        value="3.30107386305461" />
      <inertia
        ixx="0.0156840898967947"
        ixy="-5.02715186795219E-05"
        ixz="0.00370191919239212"
        iyy="0.0190640369026902"
        iyz="-0.000108844399448207"
        izz="0.0122287954475827" />
    </inertial>
    <visual>
      <origin
        xyz="0 0 0"
        rpy="0 0 0" />
      <geometry>
        <mesh
          filename="package://efort_description/meshes/link_1.STL" />
      </geometry>
      <material
        name="">
        <color
          rgba="0.792156862745098 0.819607843137255 0.933333333333333 1" />
      </material>
    </visual>
    <collision>
      <origin
        xyz="0 0 0"
        rpy="0 0 0" />
      <geometry>
        <mesh
          filename="package://efort_description/meshes/link_1.STL" />
      </geometry>
    </collision>
  </link>
  <joint
    name="joint_1"
    type="revolute">
    <origin
      xyz="0 0 0.1815"
      rpy="-3.1579E-17 -7.9306E-17 -2.446E-16" />
    <parent
      link="base_link" />
    <child
      link="link_1" />
    <axis
      xyz="0 0 1" />
    <limit
      lower="-2.915"
      upper="2.915"
      effort="0"
      velocity="0" />
  </joint>
  <link
    name="link_2">
    <inertial>
      <origin
        xyz="0.11946545795155 0.00418067503015646 0.000132410986333669"
        rpy="0 0 0" />
      <mass
        value="5.66418816925894" />
      <inertia
        ixx="0.0420072797046599"
        ixy="0.000187057702251965"
        ixz="0.000602757828853935"
        iyy="0.096526192549623"
        iyz="-3.1355093756289E-06"
        izz="0.0681190682039788" />
    </inertial>
    <visual>
      <origin
        xyz="0 0 0"
        rpy="0 0 0" />
      <geometry>
        <mesh
          filename="package://efort_description/meshes/link_2.STL" />
      </geometry>
      <material
        name="">
        <color
          rgba="0.792156862745098 0.819607843137255 0.933333333333333 1" />
      </material>
    </visual>
    <collision>
      <origin
        xyz="0 0 0"
        rpy="0 0 0" />
      <geometry>
        <mesh
          filename="package://efort_description/meshes/link_2.STL" />
      </geometry>
    </collision>
  </link>
  <joint
    name="joint_2"
    type="revolute">
    <origin
      xyz="0.05 0 0.14"
      rpy="1.5708 -1.5708 0" />
    <parent
      link="link_1" />
    <child
      link="link_2" />
    <axis
      xyz="0 0 1" />
    <limit
      lower="-2.269"
      upper="1.571"
      effort="0"
      velocity="0" />
  </joint>
  <link
    name="link_3">
    <inertial>
      <origin
        xyz="0.0689126182685479 -0.0180608732958353 -0.000210161459564274"
        rpy="0 0 0" />
      <mass
        value="2.3749746553772" />
      <inertia
        ixx="0.0124152997750259"
        ixy="-0.000234812353660264"
        ixz="3.44073018993852E-05"
        iyy="0.00474437835451971"
        iyz="-8.9572649241132E-06"
        izz="0.0138952612877989" />
    </inertial>
    <visual>
      <origin
        xyz="0 0 0"
        rpy="0 0 0" />
      <geometry>
        <mesh
          filename="package://efort_description/meshes/link_3.STL" />
      </geometry>
      <material
        name="">
        <color
          rgba="0.792156862745098 0.819607843137255 0.933333333333333 1" />
      </material>
    </visual>
    <collision>
      <origin
        xyz="0 0 0"
        rpy="0 0 0" />
      <geometry>
        <mesh
          filename="package://efort_description/meshes/link_3.STL" />
      </geometry>
    </collision>
  </link>
  <joint
    name="joint_3"
    type="revolute">
    <origin
      xyz="0.27 0 0"
      rpy="3.7255E-32 -4.4742E-16 -2.0817E-16" />
    <parent
      link="link_2" />
    <child
      link="link_3" />
    <axis
      xyz="0 0 1" />
    <limit
      lower="-1.309"
      upper="1.833"
      effort="0"
      velocity="0" />
  </joint>
  <link
    name="link_4">
    <inertial>
      <origin
        xyz="-5.26226862640478E-07 0.00024724190038449 -0.074929998229337"
        rpy="0 0 0" />
      <mass
        value="1.57891879485757" />
      <inertia
        ixx="0.00708604457985196"
        ixy="-2.63762869617243E-08"
        ixz="-5.47864365917456E-08"
        iyy="0.00494844971433659"
        iyz="2.10513254753591E-05"
        izz="0.00408041413848916" />
    </inertial>
    <visual>
      <origin
        xyz="0 0 0"
        rpy="0 0 0" />
      <geometry>
        <mesh
          filename="package://efort_description/meshes/link_4.STL" />
      </geometry>
      <material
        name="">
        <color
          rgba="0.752941176470588 0.752941176470588 0.752941176470588 1" />
      </material>
    </visual>
    <collision>
      <origin
        xyz="0 0 0"
        rpy="0 0 0" />
      <geometry>
        <mesh
          filename="package://efort_description/meshes/link_4.STL" />
      </geometry>
    </collision>
  </link>
  <joint
    name="joint_4"
    type="continuous">
    <origin
      xyz="0.07 -0.299 0"
      rpy="-1.5708 -2.6129E-16 -3.1416" />
    <parent
      link="link_3" />
    <child
      link="link_4" />
    <axis
      xyz="0 0 1" />
    <limit
      lower="-3.142"
      upper="3.142"
      effort="0"
      velocity="0" />
  </joint>
  <link
    name="link_5">
    <inertial>
      <origin
        xyz="0 -0.000183640639932092 7.24280138444819E-17"
        rpy="0 0 0" />
      <mass
        value="0.268007889474162" />
      <inertia
        ixx="0.00035328124873452"
        ixy="2.38919329368297E-19"
        ixz="-9.01159050174182E-21"
        iyy="0.000211009992076537"
        iyz="3.26637229076845E-20"
        izz="0.00040348650712656" />
    </inertial>
    <visual>
      <origin
        xyz="0 0 0"
        rpy="0 0 0" />
      <geometry>
        <mesh
          filename="package://efort_description/meshes/link_5.STL" />
      </geometry>
      <material
        name="">
        <color
          rgba="1 1 1 1" />
      </material>
    </visual>
    <collision>
      <origin
        xyz="0 0 0"
        rpy="0 0 0" />
      <geometry>
        <mesh
          filename="package://efort_description/meshes/link_5.STL" />
      </geometry>
    </collision>
  </link>
  <joint
    name="joint_5"
    type="revolute">
    <origin
      xyz="0 0 0"
      rpy="1.5708 -2.9596E-33 1.5296E-16" />
    <parent
      link="link_4" />
    <child
      link="link_5" />
    <axis
      xyz="0 0 1" />
    <limit
      lower="-1.919"
      upper="1.919"
      effort="0"
      velocity="0" />
  </joint>
  <link
    name="link_6">
     <visual>
      <origin
        xyz="0 0 0"
        rpy="0 0 0" />
      <geometry>
        <mesh
          filename="package://efort_description/meshes/link_6.STL" />
      </geometry>
      <material
        name="">
        <color
          rgba="0.792156862745098 0.819607843137255 0.933333333333333 1" />
      </material>
    </visual>
    <collision>
      <origin
        xyz="0 0 0"
        rpy="0 0 0" />
      <geometry>
        <mesh
          filename="package://efort_description/meshes/link_6.STL" />
      </geometry>
    </collision>
  </link>
  <joint
    name="joint_6"
    type="continuous">
    <origin
      xyz="0 0.0785 0"
      rpy="1.5708 6.4983E-17 3.1416" />
    <parent
      link="link_5" />
    <child
      link="link_6" />
    <axis
      xyz="0 0 1" />
  </joint>
</robot>
